Workbook
Name Slicer_Bonus_Performance: #N/A
Name Slicer_Months__Hire_Date: #N/A
Name Slicer_Years: #N/A
Name Slicer_Years_of_Service: #N/A

Sheet Raw_Employee_Data
A1: Emp ID | B1: First_Name | C1: Last_Name | D1: Dept Code | E1: Hire Date | F1: Salary | G1: Perf_Score | H1: Employment Status
A2: EMP127 | B2: Emily | C2: Brown | D2: IT02 | E2: 43093 | F2: 50361 | G2: 52 | H2: active
A3: EMP046 | B3: Richard | C3: Hernandez | D3: MKT04 | E3: 44659 | F3: 112673 | H3: ACTIVE
A4: EMP134 | B4: Emily | C4: Gonzalez | D4: IT02 | E4: 42431 | F4: $114,425 | G4: 54 | H4: LEFT
A5: EMP139 | B5: John | C5: Martinez | D5: FIN03 | E5: 45110 | F5: 103831 | G5: 70 | H5: active
A6: EMP112 | B6: Thomas | C6: Smith | D6: IT02 | E6: 44977 | F6: 73785 | G6: 40 | H6: Left
A7: EMP030 | B7: Emily | C7: Johnson | D7: OPS06 | E7: 02-Mar-20 | F7: 115882 | G7: 49 | H7: ACTIVE
A8: EMP096 | B8: John | C8: Wilson | D8: OPS06 | E8: 45272 | F8: 59980 | G8: 70 | H8: Left
A9: EMP098 | B9: Jessica | C9: Smith | D9: OPS06 | E9: 44174 | F9: 68728 | G9: 45 | H9: ACTIVE
A10: EMP095 | C10: Rodriguez | D10: FIN03 | E10: 43107 | F10: 102139 | G10: 79 | H10: active
A11: EMP140 | B11: Michael | C11: Martinez | D11: SAL05 | E11: 42676 | F11: 94998 | G11: 58 | H11: Active
A12: EMP020 | B12: Emily | C12: Miller | D12: sal05 | E12: 43911 | F12: $118,635 | G12: 49 | H12: Active
A13: EMP057 | B13: Emily | C13: Hernandez | D13: IT02 | E13: 42425 | F13: 76918 | G13: 62 | H13: Actv
A14: EMP016 | B14: Jane | C14: Williams | D14: mkt04 | E14: 17-Jun-21 | F14: 61408 | G14: 48 | H14: ACTIVE
A15: EMP070 | B15: Jane | C15: Miller | D15: MKT04 | E15: 44001 | F15: 99990 | G15: 54 | H15: Actv
A16: EMP025 | B16: Robert | C16: Jones | D16: MKT04 | E16: 43820 | F16: 80385 | H16: active
A17: EMP031 | B17: Thomas | C17: Rodriguez | D17: SAL05 | E17: 45169 | F17: 65290 | G17: 77 | H17: active
A18: EMP126 | B18: Emily | C18: Davis | D18: IT02 | E18: 42337 | F18: 105765 | G18: 42 | H18: Active
A19: EMP109 | B19: James | C19: Martinez | D19: SAL05 | E19: 42899 | F19: 102921 | G19: 49 | H19: ACTIVE
A20: EMP066 | B20: Ashley | C20: Lopez | D20: MKT04 | E20: 43235 | F20: 73984 | G20: 93 | H20: Actv
A21: EMP120 | B21: Amanda | C21: Gonzalez | D21: IT02 | E21: 42575 | G21: 75 | H21: Actv
A22: EMP019 | B22: Michael | C22: Hernandez | D22: FIN03 | E22: 43076 | F22: 118527 | G22: 50 | H22: Actv
A23: EMP013 | B23: Richard | C23: Hernandez | D23: MKT04 | E23: 44353 | F23: 107871 | G23: 88 | H23: active
A24: EMP010 | B24: Michael | C24: Rodriguez | D24: IT02 | E24: 44815 | F24: 93956 | G24: 50 | H24: LEFT
A25: EMP032 | B25: Jessica | C25: Johnson | D25: FIN03 | E25: 42565 | F25: 100851 | G25: 64 | H25: ACTIVE
A26: EMP082 | B26: Ashley | C26: Williams | D26: SAL05 | E26: 44728 | F26: 68655 | G26: 32 | H26: active
A27: EMP052 | C27: Williams | D27: SAL05 | E27: 45134 | F27: 81205 | G27: 59 | H27: Actv
A28: EMP129 | B28: John | C28: Wilson | D28: SAL05 | E28: 09/24/2019 | F28: $77,610 | G28: 88 | H28: Actv
A29: EMP146 | B29: Thomas | C29: Rodriguez | D29: it02 | E29: 44765 | F29: $50,873 | G29: 90 | H29: Active
A30: EMP099 | B30: Michael | C30: Wilson | D30: fin03 | E30: 13-May-18 | F30: 85312 | G30: 66 | H30: active
A31: EMP015 | B31: John | C31: Rodriguez | D31: SAL05 | E31: 42202 | G31: 68 | H31: active
A32: EMP076 | B32: Thomas | C32: Hernandez | D32: OPS06 | E32: 05-Aug-15 | F32: 97055 | G32: 80 | H32: Actv
A33: EMP137 | B33: Michael | C33: Johnson | D33: IT02 | E33: 45195 | F33: 66069 | G33: 72 | H33: Actv
A34: EMP056 | B34: Sarah | C34: Brown | D34: it02 | E34: 10-Jun-19 | F34: 90157 | G34: 58 | H34: active
A35: EMP125 | B35: Jane | C35: Martinez | D35: HR01 | E35: 44578 | F35: 59899 | G35: 78 | H35: Actv
A36: EMP085 | B36: Emily | C36: Jones | D36: FIN03 | E36: 03-Jul-17 | F36: 113389 | G36: 30 | H36: ACTIVE
A37: EMP106 | C37: Brown | D37: IT02 | E37: 01-Sep-15 | F37: 102691 | G37: 52 | H37: Active
A38: EMP043 | B38: John | C38: Wilson | D38: OPS06 | E38: 03-Aug-22 | F38: 111845 | G38: 98 | H38: active
A39: EMP068 | B39: Melissa | C39: Brown | D39: SAL05 | E39: 06/29/2022 | F39: 69219 | G39: 93 | H39: Actv
A40: EMP128 | B40: Michael | C40: Smith | D40: FIN03 | E40: 43949 | G40: 80 | H40: left
...

Sheet Analysis
A3: Total Employee | C3: Department | D3: Sum of Salary | F3: Department | G3: Count of Department_Name
A4: 145 | B4: =GETPIVOTDATA("Emp_ID",$A$3) -> 145 | C4: Finance | D4: 1477866 | F4: Finance | G4: 17
C5: Human Resources | D5: 1336433 | F5: Human Resources | G5: 17
C6: Information Technology | D6: 2923918 | F6: Information Technology | G6: 33
C7: Marketing | D7: 1754482 | F7: Marketing | G7: 20
C8: Operations | D8: 2189534 | F8: Operations | G8: 29
C9: Sales | D9: 2248862 | F9: Sales | G9: 29
C10: Grand Total | D10: 11931095 | E10: =GETPIVOTDATA("Salary",$C$3) -> 11931095 | F10: Grand Total | G10: 145
A12: Department | B12: Count of Emp_ID | D12: Employment Status | E12: Average of Performance_Score | G12: Average of Salary
A13: Active | B13: 0.77241379 | D13: Active | E13: 67.353056 | G13: 82283.414 | H13: =GETPIVOTDATA("Salary",$G$12) -> 82283.414
A14: Finance | B14: 0.082758621 | C14: =GETPIVOTDATA("Emp_ID",$A$12,"Employment_Status","Left")+GETPIVOTDATA("Emp_ID",$A$12,"Employment_Status","Resigned") -> 0.22758621 | D14: Left | E14: 68.307716
A15: Human Resources | B15: 0.096551724 | D15: Resigned | E15: 71.7
A16: Information Technology | B16: 0.1862069 | D16: Grand Total | E16: 67.804274
A17: Marketing | B17: 0.10344828 | G17: Row Labels | H17: Sum of Salary
A18: Operations | B18: 0.15862069 | G18: 2015 | H18: 1022704
A19: Sales | B19: 0.14482759 | D19: Performance Band | E19: Sum of Bonus_Performance | G19: 2016 | H19: 1599529
A20: Left | B20: 0.15862069 | D20: Achieving | E20: 2.1 | G20: 2017 | H20: 1437328
A21: Finance | B21: 0.027586207 | D21: Exceeding | E21: 1.68 | G21: 2018 | H21: 1517433
A22: Human Resources | B22: 0.0068965517 | D22: Outstanding | E22: 1.08 | G22: 2019 | H22: 1271858
A23: Information Technology | B23: 0.034482759 | D23: Developing | E23: 0.88 | G23: 2020 | H23: 1304199
A24: Marketing | B24: 0.020689655 | D24: Needs Improvement | E24: 0 | G24: 2021 | H24: 1221472
A25: Operations | B25: 0.034482759 | D25: Grand Total | E25: 5.74 | G25: 2022 | H25: 1345437
A26: Sales | B26: 0.034482759 | G26: 2023 | H26: 1211135
A27: Resigned | B27: 0.068965517 | G27: Grand Total | H27: 11931095
A28: Finance | B28: 0.0068965517
A29: Human Resources | B29: 0.013793103
A30: Information Technology | B30: 0.0068965517
A31: Marketing | B31: 0.013793103
A32: Operations | B32: 0.0068965517
A33: Sales | B33: 0.020689655
A34: Grand Total | B34: 1

Sheet Dashboard

Sheet dataset
A1: Emp_ID | B1: First_Name | C1: Last_Name | D1: Full_Name | E1: Department_Code | F1: Hire_Date | G1: Salary | H1: Performance_Score | I1: Employment_Status | J1: Department_Name | K1: Performance_Band | L1: Bonus_Performance | M1: Years | N1: Years_of_Service
A2: EMP127 | B2: Emily | C2: Brown | D2: Emily Brown | E2: IT02 | F2: 43093 | G2: 50361 | H2: 52 | I2: Active | J2: =VLOOKUP(E2,Lookup_Departments!$A$1:$B$7,2,FALSE) -> Information Technology | K2: =VLOOKUP(H2,Lookup_Performance!$A$1:$D$6,3,TRUE) -> Developing | L2: =VLOOKUP(H2,Lookup_Performance!$A$1:$D$6,4,TRUE) -> 0.02 | M2: =TEXT(F2, "yyyy") -> 2017 | N2: 9
A3: EMP046 | B3: Richard | C3: Hernandez | D3: Richard Hernandez | E3: MKT04 | F3: 44777 | G3: 112673 | H3: 68.077465 | I3: Active | J3: =VLOOKUP(E3,Lookup_Departments!$A$1:$B$7,2,FALSE) -> Marketing | K3: =VLOOKUP(H3,Lookup_Performance!$A$1:$D$6,3,TRUE) -> Developing | L3: =VLOOKUP(H3,Lookup_Performance!$A$1:$D$6,4,TRUE) -> 0.02 | M3: =TEXT(F3, "yyyy") -> 2022 | N3: 4
A4: EMP134 | B4: Emily | C4: Gonzalez | D4: Emily Gonzalez | E4: IT02 | F4: 42403 | G4: 114425 | H4: 54 | I4: Left | J4: =VLOOKUP(E4,Lookup_Departments!$A$1:$B$7,2,FALSE) -> Information Technology | K4: =VLOOKUP(H4,Lookup_Performance!$A$1:$D$6,3,TRUE) -> Developing | L4: =VLOOKUP(H4,Lookup_Performance!$A$1:$D$6,4,TRUE) -> 0.02 | M4: =TEXT(F4, "yyyy") -> 2016 | N4: 10
A5: EMP139 | B5: John | C5: Martinez | D5: John Martinez | E5: FIN03 | F5: 44992 | G5: 103831 | H5: 70 | I5: Active | J5: =VLOOKUP(E5,Lookup_Departments!$A$1:$B$7,2,FALSE) -> Finance | K5: =VLOOKUP(H5,Lookup_Performance!$A$1:$D$6,3,TRUE) -> Achieving | L5: =VLOOKUP(H5,Lookup_Performance!$A$1:$D$6,4,TRUE) -> 0.05 | M5: =TEXT(F5, "yyyy") -> 2023 | N5: 3
A6: EMP112 | B6: Thomas | C6: Smith | D6: Thomas Smith | E6: IT02 | F6: 44977 | G6: 73785 | H6: 40 | I6: Left | J6: =VLOOKUP(E6,Lookup_Departments!$A$1:$B$7,2,FALSE) -> Information Technology | K6: =VLOOKUP(H6,Lookup_Performance!$A$1:$D$6,3,TRUE) -> Needs Improvement | L6: =VLOOKUP(H6,Lookup_Performance!$A$1:$D$6,4,TRUE) -> 0 | M6: =TEXT(F6, "yyyy") -> 2023 | N6: 3
A7: EMP030 | B7: Emily | C7: Johnson | D7: Emily Johnson | E7: OPS06 | F7: 43864 | G7: 115882 | H7: 49 | I7: Active | J7: =VLOOKUP(E7,Lookup_Departments!$A$1:$B$7,2,FALSE) -> Operations | K7: =VLOOKUP(H7,Lookup_Performance!$A$1:$D$6,3,TRUE) -> Needs Improvement | L7: =VLOOKUP(H7,Lookup_Performance!$A$1:$D$6,4,TRUE) -> 0 | M7: =TEXT(F7, "yyyy") -> 2020 | N7: 6
A8: EMP096 | B8: John | C8: Wilson | D8: John Wilson | E8: OPS06 | F8: 45272 | G8: 59980 | H8: 70 | I8: Left | J8: =VLOOKUP(E8,Lookup_Departments!$A$1:$B$7,2,FALSE) -> Operations | K8: =VLOOKUP(H8,Lookup_Performance!$A$1:$D$6,3,TRUE) -> Achieving | L8: =VLOOKUP(H8,Lookup_Performance!$A$1:$D$6,4,TRUE) -> 0.05 | M8: =TEXT(F8, "yyyy") -> 2023 | N8: 3
A9: EMP098 | B9: Jessica | C9: Smith | D9: Jessica Smith | E9: OPS06 | F9: 44086 | G9: 68728 | H9: 45 | I9: Active | J9: =VLOOKUP(E9,Lookup_Departments!$A$1:$B$7,2,FALSE) -> Operations | K9: =VLOOKUP(H9,Lookup_Performance!$A$1:$D$6,3,TRUE) -> Needs Improvement | L9: =VLOOKUP(H9,Lookup_Performance!$A$1:$D$6,4,TRUE) -> 0 | M9: =TEXT(F9, "yyyy") -> 2020 | N9: 6
A10: EMP095 | B10: Emily | C10: Rodriguez | D10: Emily Rodriguez | E10: sal05 | F10: 43282 | G10: 94998 | H10: 58 | I10: Active | J10: =VLOOKUP(E10,Lookup_Departments!$A$1:$B$7,2,FALSE) -> Sales | K10: =VLOOKUP(H10,Lookup_Performance!$A$1:$D$6,3,TRUE) -> Developing | L10: =VLOOKUP(H10,Lookup_Performance!$A$1:$D$6,4,TRUE) -> 0.02 | M10: =TEXT(F10, "yyyy") -> 2018 | N10: 8
A11: EMP140 | B11: Michael | C11: Martinez | D11: Michael Martinez | E11: IT02 | F11: 42411 | G11: 118635 | H11: 49 | I11: Active | J11: =VLOOKUP(E11,Lookup_Departments!$A$1:$B$7,2,FALSE) -> Information Technology | K11: =VLOOKUP(H11,Lookup_Performance!$A$1:$D$6,3,TRUE) -> Needs Improvement | L11: =VLOOKUP(H11,Lookup_Performance!$A$1:$D$6,4,TRUE) -> 0 | M11: =TEXT(F11, "yyyy") -> 2016 | N11: 10
A12: EMP020 | B12: Emily | C12: Miller | D12: Emily Miller | E12: mkt04 | F12: 43911 | G12: 76918 | H12: 62 | I12: Active | J12: =VLOOKUP(E12,Lookup_Departments!$A$1:$B$7,2,FALSE) -> Marketing | K12: =VLOOKUP(H12,Lookup_Performance!$A$1:$D$6,3,TRUE) -> Developing | L12: =VLOOKUP(H12,Lookup_Performance!$A$1:$D$6,4,TRUE) -> 0.02 | M12: =TEXT(F12, "yyyy") -> 2020 | N12: 6
A13: EMP057 | B13: Emily | C13: Hernandez | D13: Emily Hernandez | E13: MKT04 | F13: 42425 | G13: 61408 | H13: 48 | I13: Active | J13: =VLOOKUP(E13,Lookup_Departments!$A$1:$B$7,2,FALSE) -> Marketing | K13: =VLOOKUP(H13,Lookup_Performance!$A$1:$D$6,3,TRUE) -> Needs Improvement | L13: =VLOOKUP(H13,Lookup_Performance!$A$1:$D$6,4,TRUE) -> 0 | M13: =TEXT(F13, "yyyy") -> 2016 | N13: 10
... A151: EMP103 | B151: Amanda | C151: Brown | D151: Av88_Amanda | E151: IT02 | F151: 44848 | G151: 118634 | H151: 91 | I151: Active | J151: =VLOOKUP(E151,Lookup_Departments!$A$1:$B$7,2,FALSE) -> Information Technology | K151: =VLOOKUP(H151,Lookup_Performance!$A$1:$D$6,3,TRUE) -> Exceeding | L151: =VLOOKUP(H151,Lookup_Performance!$A$1:$D$6,4,TRUE) -> 0.08 | M151: =TEXT(F151, "yyyy") -> 2022 | N151: 4

Sheet Lookup_Departments
A1: Dept_Code | B1: Department_Name
A2: HR01 | B2: Human Resources
A3: IT02 | B3: Information Technology
A4: FIN03 | B4: Finance
A5: MKT04 | B5: Marketing
A6: SAL05 | B6: Sales
A7: OPS06 | B7: Operations

Sheet Lookup_Performance
A1: Min_Score | B1: Max_Score | C1: Performance_Band | D1: Bonus_Percentage
A2: 0 | B2: 49 | C2: Needs Improvement | D2: 0
A3: 50 | B3: 69 | C3: Developing | D3: 0.02
A4: 70 | B4: 84 | C4: Achieving | D4: 0.05
A5: 85 | B5: 94 | C5: Exceeding | D5: 0.08
A6: 95 | B6: 100 | C6: Outstanding | D6: 0.12
